Workbook
Name Liste_Besoin: Listes!$E$2:$E$6
Name Liste_CanalRelance: Listes!$G$2:$G$4
Name Liste_Objection: Listes!$F$2:$F$6
Name Liste_OuiNon: Listes!$B$2:$B$3
Name Liste_QualiteSite: Listes!$C$2:$C$5
Name Liste_Score: Listes!$I$2:$I$6
Name Liste_SiteWeb: Listes!$A$2:$A$8
Name Liste_StatutAppel: Listes!$D$2:$D$6
Name Liste_StatutRelance: Listes!$H$2:$H$4

Sheet Suivi Prospects
A1: N/ Studio Digital — Fichier de Prospection Téléphonique
A2: DES SITES QUI TRAVAILLENT. DES RÉSULTATS QUI COMPTENT.
A3: ① INFOS ENTREPRISE | N3: ② PRÉSENCE EN LIGNE | S3: ③ APPEL | W3: ④ RÉSULTAT APPEL | X3: ⑤ BESOIN IDENTIFIÉ | Y3: ⑥ OBJECTION | Z3: ⑦ COMMENTAIRE & RELANCE | AF3: ⑧ SUIVI COMMERCIAL
A4: Nom entreprise | B4: Type de commerce | C4: Ville | D4: Téléphone | E4: Email | F4: Site web (type) | G4: URL site web | H4: Instagram (O/N) | I4: URL Instagram | J4: Facebook (O/N) | K4: URL Facebook | L4: Nom dirigeant | M4: Fonction | N4: Fiche Google complète ? | O4: Qualité site | P4: Note Google | Q4: Nb avis Google | R4: Accroche appel 🎯 | S4: Date appel | T4: Heure | U4: A répondu ? | V4: Durée (min) | W4: Statut appel | X4: Besoin identifié | Y4: Objection | Z4: Commentaire libre 📝 | AA4: Date relance | AB4: Canal relance | AC4: Statut relance | AD4: RDV prévu (date) | AE4: RDV réalisé ? | AF4: Devis envoyé ? | AG4: Client signé ? | AH4: Montant (€) | AI4: Score 🔥 (1 à 5)
A5: Le Paradis de la Coiffure | B5: Salon de coiffure | C5: Rillieux-la-Pape | D5: 04 78 88 07 00 | F5: Planity | G5: https://www.planity.com/le-paradis-de-la-coiffure-69140-rillieux-la-pape | H5: Oui | I5: https://www.instagram.com/leparadisdelacoiffure/ | J5: Oui | K5: https://www.facebook.com/Leparadisdelacoiffure | L5: Juliette et Charlène | M5: ? | N5: Oui | O5: Inexistant | P5: 4.5 | Q5: 95 | R5: Photos pourries | S5: 45819 | T5: 0.66666667 | U5: Oui | V5: 1 | W5: Refus | X5: Aucun besoin | Y5: Autre | Z5: Nre veut pas de site ce suffit des réseaux Sociaux | AA5: 46367 | AB5: Appel | AC5: À faire | AE5: Non | AF5: Non | AG5: Non | AH5: 0 | AI5: 1 ❄❄
A6: Micilia Coiffure | B6: Salon de coiffure | C6: Rillieux-la-Pape | D6: +33 4 78 88 86 64 | E6: miciliacoiffure@gmail.com | F6: Planity | G6: https://www.planity.com/micilia-coiffure-69140-rillieux-la-pape | H6: Oui | I6: https://www.instagram.com/miciliacoiffure/ | J6: Oui | K6: https://www.facebook.com/profile.php?id=100054506018787 | L6: Magalie et Gaëlle | M6: ? | N6: Oui | O6: Inexistant | P6: 4.8 | Q6: 83 | R6: Photos pas très attrayantes | S6: 45819 | T6: 0.67361111 | U6: Oui | V6: 1 | W6: Refus | X6: Aucun besoin | Y6: Pas intéressé | AA6: 46367 | AB6: Appel | AC6: À faire | AE6: Non | AF6: Non | AG6: Non | AH6: 0 | AI6: 1 ❄❄
A7: Coiffure Patrick et Sylviane | B7: Salon de coiffure | C7: Rillieux-la-Pape | D7: +33 4 78 88 54 36 | F7: Aucun | H7: Oui | I7: https://www.instagram.com/coiffurepatricketsylvain/ | J7: Non | L7: Patrick | M7: Gérant | N7: Non | O7: Inexistant | P7: 4.9 | Q7: 69 | R7: Déjà, on sait pas si c'est Patrick et Sylvain ou Patrick et Sylviane. Juste Instagram et quasi inexistants 3 photos | S7: 45819 | T7: 0.67569444 | U7: Oui | V7: 1 | W7: Refus | X7: Aucun besoin | Y7: Pas intéressé | Z7: Refus catégorique | AA7: 46367 | AB7: Appel | AC7: À faire | AE7: Non | AF7: Non | AG7: Non | AH7: 0 | AI7: 1 ❄❄
A8: Sab'Styl Coiffure | B8: Salon de coiffure | C8: Rillieux-la-Pape | D8: +33 4 78 88 91 39 | E8: sabrina-231@outlook.fr | F8: Planity | G8: https://www.planity.com/sabstyl-coiffure-69140-rillieux-la-pape | H8: Oui | I8: https://www.instagram.com/sabrinatendance?fbclid=IwY2xjawSP9OZleHRuA2FlbQIxMABicmlkETBRRlhsdmpYVXh0MHhNa2Roc3J0YwZhcHBfaWQQMjIyMDM5MTc4ODIwMDg5MgABHtZV0yq08VAV40lMuumv82scfkthim_feabqyEV6gM9Ch63Rbt7jsbB_Y9sn_aem_kUxqBasjjTE_L96FQxw6Hw | J8: Oui | K8: https://www.facebook.com/profile.php?id=100063578890413# | L8: Sabrina | M8: Gérante | N8: Non | O8: Inexistant | P8: 4.7 | Q8: 66 | R8: Fiche Google totalement insatisfaisante, Insta et Facebook, photos assez récentes, juste Planity | S8: 46192 | T8: 0.78819444 | W8: À rappeler | AA8: 46191 | AB8: Appel | AC8: À faire | AE8: Non | AF8: Non | AG8: Non | AH8: 0
A9: La Loge Coiffeur Créateur | B9: Salon de coiffure | C9: Rillieux-la-Pape | D9: +33 4 28 29 85 58 | F9: Planity | G9: https://www.planity.com/la-loge-coiffeur-createur-69140-rillieux-la-pape | H9: Oui | I9: https://www.instagram.com/la_loge_rillieux/?hl=frc | J9: Non | L9: Sam | M9: Gérante | N9: Non | O9: Inexistant | P9: 4.1 | Q9: 156 | R9: Ne font pas que de la coiffure, aussi esthéticienne. Photos moyennes sur Insta | S9: 46184 | T9: 0.70833333 | U9: Non | W9: À rappeler | Z9: A rappeler le 12/06/2026 à partir de 10h et demander Sam | AE9: Non | AF9: Non | AG9: Non | AH9: 0
A10: Coiffure Symbiose | B10: Salon de coiffure | C10: Rillieux-la-Pape | D10: +33 4 78 88 03 30 | F10: Aucun | H10: Non | J10: Oui | K10: https://www.facebook.com/severinecoiffuresymbiose/photos?locale=fr_FR | L10: ? | M10: ? | N10: Non | O10: Inexistant | P10: 4.5 | Q10: 41 | R10: Prise de RDV sur Facebook, pas d'instagram, fiche Google sans lien vers Facebook - Nul | S10: 46184 | T10: 0.71180556 | U10: Oui | V10: 1 | W10: Refus | X10: Aucun besoin | Y10: Pas intéressé | Z10: Ne veux pas de site internet catégorique | AA10: 46367 | AB10: Appel | AC10: À faire | AE10: Non | AF10: Non | AG10: Non | AH10: 0 | AI10: 1 ❄❄
A11: Steph Coiff à Dom | B11: Coiffure à domicile | C11: Rillieux-la-Pape | D11: +33 6 26 62 73 31 | F11: Vrai site | G11: https://www.stephcoiffadom.com/ | H11: Oui | I11: https://www.instagram.com/stephcoiffadom/ | J11: Non | L11: Stéphanie | M11: Gérante | N11: Non | O11: Mauvais | P11: 5.0 | Q11: 11 | R11: Pas de Facebook, pas de lien sur son Insta via Google Business. Site existant mais très veillissant sans prise de rdv en ligne | W11: Non joint | AE11: Non | AF11: Non | AG11: Non | AH11: 0
A12: Yesillim Beauté | B12: Institut esthétique / Épilation | C12: Rillieux-la-Pape | D12: +33 4 78 88 04 29 | E12: yesillimbeaute@outlook.com | F12: Planity et Treatwell | G12: https://www.planity.com/yesillim-beaute-69140-rillieux-la-pape-u9h | H12: Oui | I12: https://www.instagram.com/explore/locations/1018286418/yesillim-beaute/ | J12: Oui | K12: https://www.facebook.com/Yesillimbeaute/?locale=fr_FR | L12: Yesilim | M12: Gérante | N12: Oui | O12: Inexistant | P12: 4.7 | Q12: 120 | R12: Elle est sur Planity et en cours sur Treatwell | S12: 46192 | T12: 0.64583333 | U12: Non | W12: Non joint | Z12: A rappeler | AA12: 46193 | AB12: Appel | AC12: À faire | AE12: Non | AF12: Non | AG12: Non | AH12: 0
A13: Galaxie My Name | B13: Institut beauté / Onglerie | C13: Rillieux-la-Pape | D13: +33 6 67 96 75 81 | F13: Planity | G13: https://www.planity.com/galaxie-my-name-69140-rillieux-la-pape | H13: Oui | I13: https://www.instagram.com/galaxie_myname | J13: Oui | K13: https://www.facebook.com/ad.intic.1/ | L13: Yasmine | M13: Gérante | N13: Non | O13: Professionnel | P13: 4.9 | Q13: 189 | R13: Site très récent à rappeler dans 6 mois au cas où… | S13: 46184 | T13: 0.65972222 | U13: Oui | V13: 1 | W13: Refus | X13: Aucun besoin | Y13: Déjà un site | Z13: Site très récent à rappeler dans 6 mois au cas où… | AA13: 46367 | AB13: Appel | AC13: À faire | AE13: Non | AF13: Non | AG13: Non | AH13: 0 | AI13: 1 ❄❄
A14: Institut Douce'Heure | B14: Institut de beauté / Spa | C14: Rillieux-la-Pape | D14: +33 4 78 88 45 44 | E14: Institutdouceheure18@gmail.com | F14: Vrai site | G14: https://www.institutdouceheure.fr/ | H14: Oui | I14: https://www.instagram.com/institutdouceheure00/?hl=fr | J14: Oui | K14: https://www.facebook.com/institutdouceheure00 | L14: Lucile | M14: Gérante | N14: Oui | O14: Mauvais | P14: 4.6 | Q14: 58 | R14: Site très limite et vieillissant | W14: Non joint | AE14: Non | AF14: Non | AG14: Non | AH14: 0
A15: By Milia OHB Institut | B15: Institut beauté / Maquillage | C15: Rillieux-la-Pape | D15: +33 6 28 92 32 85 | F15: Vrai site | G15: https://bymiliaohb.com/ | H15: Oui | I15: https://www.instagram.com/miliaohbmakeup/ | J15: Oui | K15: https://www.facebook.com/profile.php?id=100045702224468&locale=mk_MK# | L15: Milia | M15: Gérante | N15: Non | O15: Professionnel | P15: 4.2 | Q15: 162 | R15: Bon site, manque juste le lien vers Facebook sur sa fiche Google Business | W15: Non joint | AE15: Non | AF15: Non | AG15: Non | AH15: 0
A16: CBeautyPerfect | B16: Onglerie | C16: Rillieux-la-Pape | D16: +33 7 67 29 52 24 | F16: Vrai site | G16: https://www.cbeautyperfect.fr/contact/ | H16: Oui | I16: https://www.instagram.com/cbeautyperfect/ | J16: Non | L16: Candice | M16: Gérante | N16: Non | O16: Professionnel | P16: 5.0 | Q16: 7 | R16: Fermeture pour congé maternité et a déjà un site pas trop mal | W16: Non joint | Z16: A rappeler car en congé maternité | AA16: 46276 | AB16: Appel | AC16: À faire | AE16: Non | AF16: Non | AG16: Non | AH16: 0
A17: Exceptionhair | B17: Institut beauté / Onglerie | C17: Rillieux-la-Pape | D17: +33 9 52 24 50 19 | E17: exceptionnail@gmail.com | F17: Aucun | H17: Non | J17: Oui | K17: https://www.facebook.com/Exceptionhair/?locale=fr_FR | L17: ? | M17: ? | N17: Oui | O17: Inexistant | P17: 4.6 | Q17: 20 | R17: Prise de RDV sur Facebook, pas d'instagram - Nul | S17: 46184 | T17: 0.72916667 | U17: Non | W17: À rappeler | Z17: Rappeler car répondeur | AA17: 46191 | AB17: Appel | AC17: À faire | AE17: Non | AF17: Non | AG17: Non | AH17: 0
A18: Manucure Russe Studio | B18: Onglerie (prothésiste ongulaire) | C18: Rillieux-la-Pape | D18: +33 7 67 14 94 53 | F18: Aucun | H18: Oui | I18: https://www.instagram.com/manucurerussestudio/ | J18: Non | L18: Sandra | M18: Gérante | N18: Oui | O18: Inexistant | P18: 5.0 | Q18: 2 | R18: Pas de prise de RDV en ligne | S18: 46184 | T18: 0.73611111 | U18: Non | W18: À rappeler | Z18: Rappeler car répondeur | AA18: 46191 | AB18: Appel | AC18: À faire | AE18: Non | AF18: Non | AG18: Non | AH18: 0
A19: Julie Tissot Réflexologue | B19: Réflexologue / Masseur | C19: Rillieux-la-Pape | D19: +33 6 09 50 90 08 | F19: Aucun | H19: Non | J19: Non | L19: Julie Tissot | M19: Praticienne | N19: Oui | O19: Inexistant | P19: 5.0 | Q19: 13 | R19: Reflexologue et auriculothérapeuthe à la polyclinique de Rilllieux - Que fiche Google | S19: 46184 | T19: 0.73958333 | U19: Non | W19: À rappeler | Z19: Rappeler car répondeur | AA19: 46191 | AB19: Appel | AC19: À faire | AE19: Non | AF19: Non | AG19: Non | AH19: 0
A20: Marco Clavero Kiné | B20: Kinésithérapeute | C20: Rillieux-la-Pape | D20: 06 11 30 98 56 | F20: Aucun | H20: Non | J20: Non | L20: Marco Clavero | M20: Kinésithérapeute | N20: Non | O20: Inexistant | P20: 5.0 | Q20: 23 | R20: Est sur plusieurs plateforme du type Doctolib, pas de numéro tel sur sa fiche Google - Ferme à 16h30 | W20: À rappeler | Z20: Rappeler car ferme à 16h30 | AA20: 46191 | AB20: Appel | AC20: À faire | AE20: Non | AF20: Non | AG20: Non | AH20: 0
A21: Patrice Renard Kiné | B21: Kinésithérapeute | C21: Rillieux-la-Pape | D21: +33 7 67 35 53 32 | F21: Aucun | H21: Non | J21: Non | L21: Patrice Renard | M21: Kinésithérapeute | N21: Non | O21: Inexistant | P21: 5.0 | Q21: 11 | R21: Pas d'horaires sur sa fiche Google - Accessible via des annuaires variés mais ne prends pas les rdv en ligne | S21: 46184 | T21: 0.74652778 | U21: Non | W21: À rappeler | Z21: Rappeler car répondeur | AA21: 46191 | AB21: Appel | AC21: À faire | AE21: Non | AF21: Non | AG21: Non | AH21: 0
A22: Lisa Lanfranchi Ostéopathe | B22: Ostéopathe | C22: Rillieux-la-Pape | D22: +33 7 85 82 48 98 | E22: lanfranchi.osteopathe@gmail.com | F22: Vrai site | G22: https://www.osteopathe-rillieux.com/ | H22: Non | J22: Oui | K22: https://www.facebook.com/p/Lisa-Lanfranchi-Ost%C3%A9opathe-61553645739992/ | L22: Lisa Lanfranchi | M22: Ostéopathe | N22: Non | O22: Passable | P22: 5.0 | Q22: 45 | R22: Site correct, juste pas les horaires sur fiche Google - A contacter plus tard pour refonte éventuellement (site de 2026) | W22: À rappeler | AA22: 46367 | AB22: Appel | AC22: À faire | AE22: Non | AF22: Non | AG22: Non | AH22: 0
A23: Elle et Lui Coiffure | B23: Salon de coiffure | C23: Sathonay-Camp | D23: +33 4 78 23 76 88 | F23: Planity | G23: https://www.planity.com/elle-coiffure-69580-sathonay-camp | H23: Oui | I23: https://www.instagram.com/salon_elle_et_lui_/ | J23: Oui | K23: https://www.facebook.com/profile.php?id=100024269928662# | L23: Marine | M23: Gérante | N23: Non | O23: Inexistant | P23: 4.8 | Q23: 100 | R23: Pas de liens facebook et Insta sur fiche Google | S23: 46192 | T23: 0.65277778 | U23: Oui | V23: 1 | W23: Refus | X23: Aucun besoin | Y23: Pas intéressé | Z23: A relancer ultérieurement | AA23: 46285 | AB23: Appel | AC23: À faire | AE23: Non | AF23: Non | AG23: Non | AH23: 0
A24: Studio Hair Sathonay | B24: Salon de coiffure | C24: Sathonay-Camp | D24: +33 4 78 23 31 80 | E24: salonstudiohair@gmail.com | F24: Planity | G24: https://www.planity.com/studio-hair-69580-sathonay-camp-dv2 | H24: Non | J24: Oui | K24: https://www.facebook.com/p/Studio-hair-100057915023434/?locale=fr_FR | L24: Anaïs | M24: Gérante | N24: Non | O24: Inexistant | P24: 4.5 | Q24: 28 | R24: Lien vers Planity, mais par vers Facebook | S24: 46192 | T24: 0.65625 | U24: Oui | V24: 1 | W24: Refus | X24: Aucun besoin | Y24: Pas intéressé | Z24: A relancer ultérieurement | AA24: 46285 | AB24: Appel | AC24: À faire | AE24: Non | AF24: Non | AG24: Non | AH24: 0
A25: Mon Cocon Douceur | B25: Institut de beauté / Spa | C25: Sathonay-Camp | D25: +33 6 95 31 09 90 | F25: Planity | G25: https://www.planity.com/mon-cocon-douceur-69580-sathonay-camp | H25: Oui | I25: https://www.instagram.com/mon_cocon_douceur/ | J25: Non | L25: Lou | M25: Gérante | N25: Non | O25: Inexistant | P25: 5.0 | Q25: 43 | R25: Lien vers Planity, mais par vers Insta | S25: 46192 | T25: 0.66319444 | U25: Oui | V25: 1 | W25: Refus | X25: Aucun besoin | Y25: Pas intéressé | Z25: Site en cours de création | AC25: Annulé | AE25: Non | AF25: Non | AG25: Non | AH25: 0
A26: Institut by Sisters | B26: Institut de beauté | C26: Sathonay-Camp | D26: +33 6 36 85 96 22 | F26: Planity | G26: https://www.planity.com/institut-by-sisters-69580-sathonay-camp | H26: Oui | I26: https://www.instagram.com/institut.by.sisters/ | J26: Non | L26: Amandine - Joana - Ilhem | M26: ? | N26: Non | O26: Inexistant | P26: 4.9 | Q26: 24 | R26: Lien vers Planity, mais par vers Insta, Institut récent Juin 2026 | S26: 46192 | T26: 0.66666667 | U26: Non | W26: À rappeler | Z26: Répondeur | AA26: 46193 | AB26: Appel | AC26: À faire | AE26: Non | AF26: Non | AG26: Non | AH26: 0
A27: L'Échoppe Beauté | B27: Institut de beauté / Onglerie | C27: Sathonay-Camp | D27: +33 9 79 16 67 79 | E27: aurelieconcept@outlook.fr | F27: Planity site vitrine | G27: https://www.lechoppebeaute.fr/#bookAppointment | H27: Oui | I27: https://www.instagram.com/l.echoppe.beaute/ | J27: Oui | K27: https://www.facebook.com/lalogebeautedaurelie/?locale=fr_FR | L27: Aurélie | M27: Gérante | N27: Non | O27: Passable | P27: 4.9 | Q27: 26 | R27: Site Planity, Fiche Google pas de liens vers Insta ou Facebook | W27: À rappeler | AA27: 46367 | AB27: Appel | AC27: À faire | AE27: Non | AF27: Non | AG27: Non | AH27: 0
A28: MANDYSSIME | B28: Onglerie | C28: Sathonay-Camp | D28: +33 7 81 04 03 29 | E28: Mandyssime.fr@gmail.com | F28: Planity | G28: https://www.planity.com/mandyssime-69580-sathonay-camp | H28: Oui | I28: https://www.instagram.com/mandyssime.fr/ | J28: Oui | K28: https://www.facebook.com/profile.php?id=61584192410337# | L28: Mandy | M28: Gérante | N28: Non | O28: Inexistant | P28: 5.0 | Q28: 38 | R28: Sur fiche Google le lien Site Web va sur son compte Insta et pas de lien pour Facebook | S28: 46192 | T28: 0.67013889 | U28: Oui | V28: 1 | W28: Refus | X28: Aucun besoin | Y28: Pas intéressé | Z28: Structure trop petite pour le moment, à quelque autour d'elle qui fait des sites internet | AA28: 46284 | AB28: Appel | AC28: À faire | AE28: Non | AF28: Non | AG28: Non | AH28: 0
A29: LM Beauty by Myriam | B29: Onglerie / Coiffure | C29: Sathonay-Camp | D29: +33 6 68 84 88 61 | F29: Lien réseaux sociaux | H29: Oui | I29: https://www.instagram.com/lmbeauty_by_myriam/ | J29: Non | L29: Myriam | M29: Gérante | N29: Oui | O29: Inexistant | P29: 5.0 | Q29: 22 | R29: Pas de site, pas de réservation sur Planity juste les horaires d'ouvertures, pas de Facebook | S29: 46192 | T29: 0.67013889 | U29: Oui | V29: 1 | W29: Refus | X29: Aucun besoin | Y29: Pas intéressé | Z29: A rappeler d'ici quelque temps | AA29: 46284 | AB29: Appel | AC29: À faire | AE29: Non | AF29: Non | AG29: Non | AH29: 0
A30: (WO)Man' Vitality | B30: Massage bien-être / Drainage | C30: Sathonay-Camp | D30: +33 7 70 48 74 90 | E30: wo.man.vitality@gmail.com | F30: Vrai site | G30: https://www.wo-man-vitality.fr/ | H30: Oui | I30: https://www.instagram.com/wo.man.vitality/ | J30: Oui | K30: https://www.facebook.com/profile.php?id=100087569314909 | L30: Manon | M30: Praticienne | N30: Oui | O30: Passable | P30: 5.0 | Q30: 51 | R30: Site internet via local & moi, bien mais franchement pas assez classe par rapport aux prestations proposées. Fiche Google bien | S30: 46192 | AE30: Non | AF30: Non | AG30: Non | AH30: 0
A31: L.M. Coiffure by Mélanie | B31: Salon de coiffure | C31: Caluire-et-Cuire | D31: +33 4 69 70 07 57 | E31: l.mcoiffure@hotmail.com | F31: Planity | G31: https://www.planity.com/lm-coiffure-by-melanie-69300-caluire-et-cuire | H31: Oui | I31: https://www.instagram.com/l.m_coiffure | J31: Oui | K31: https://www.facebook.com/lm.coiffurebymel | L31: Mélanie | M31: Gérante | N31: Oui | O31: Inexistant | P31: 4.8 | Q31: 205 | R31: Pas de site, mais bonne communication sur Facebook et Insta | S31: 46192 | T31: 0.67361111 | U31: Oui | V31: 2 | W31: Refus | X31: Aucun besoin | Y31: Pas intéressé | Z31: A rappeler ultérieurement | AA31: 46275 | AB31: Appel | AC31: À faire | AE31: Non | AF31: Non | AG31: Non | AH31: 0
A32: Cécile Coiffure | B32: Salon de coiffure | C32: Caluire-et-Cuire | D32: +33 4 78 23 21 03 | F32: Vrai site | G32: http://coiffurececilecaluire.com/ | H32: Oui | I32: https://www.instagram.com/coiffure_cecile/ | J32: Oui | K32: https://www.facebook.com/p/Marc-Pelle-100001470703509/ | L32: Marc | M32: Gérant | N32: Non | O32: Passable | P32: 4.8 | Q32: 279 | R32: Site moyen, sans lien vers Planity et pas de lien Insta et Planity sur fiche Google | S32: 46192 | AE32: Non | AF32: Non | AG32: Non | AH32: 0
A33: Contraste | B33: Salon de coiffure | C33: Caluire-et-Cuire | D33: +33 9 78 81 22 81 | F33: Planity | G33: https://www.planity.com/contraste-69300-caluire-et-cuire | H33: Oui | I33: https://www.instagram.com/contraste.caluire/ | J33: Oui | K33: https://www.facebook.com/contrastecaluire/ | L33: Marie | M33: Gérante | N33: Non | O33: Inexistant | P33: 4.9 | Q33: 59 | R33: Juste Planity, manque lien vers Facebook et lien Instagram erroné | S33: 46192 | T33: 0.68055556 | U33: Oui | V33: 10 | W33: Intéressé | X33: Veut développer | Z33: J'ai proposé à Karine un site vitrine à 300€, envoi sms avec lien site | AE33: Non | AF33: Non | AG33: Non | AH33: 0
A34: Roberto Stari Salon Caluire | B34: Salon de coiffure | C34: Caluire-et-Cuire | D34: +33 4 72 27 15 74 | E34: contact@robertostari.fr | F34: Vrai site | G34: https://www.robertostari.fr/caluire-et-cuire?gad_source=1&gad_campaignid=1698196956&gbraid=0AAAAADFl_buZKpNv55WYonvLLeNBOvemJ&gclid=Cj0KCQjwrs7RBhDuARIsAIVfBD0tGrAwLMY9KjCZmMO64wvqydGabrWitjJPLCosGbFkh9h27k1YC3gaAsLrEALw_wcB | H34: Oui | I34: https://www.instagram.com/roberto_stari_officiel | J34: Oui | K34: https://www.facebook.com/RobertoStari.Officiel/?locale=fr_FR | L34: Roberto | M34: Gérant | N34: Non | O34: Passable | P34: 4.7 | Q34: 192 | R34: Chaine de 10 salons de coiffure avec boutique en ligne. Site un peu vieillissant et manque lien Facebook sur figche Google | S34: 46192 | AE34: Non | AF34: Non | AG34: Non | AH34: 0
A35: Les Saisons by Christian Noël | B35: Salon de coiffure | C35: Caluire-et-Cuire | D35: +33 4 72 00 90 11 | E35: lessaisonsbycn@gmail.com | F35: Vrai site | G35: https://coiffurelessaisons.fr/ | H35: Oui | I35: https://www.instagram.com/lessaisonsbycn/ | J35: Oui | K35: https://www.facebook.com/lessaisonsbycn/?locale=fr_FR | L35: Christian Noël | M35: Gérant | N35: Non | O35: Professionnel | P35: 4.7 | Q35: 90 | R35: Site avec boutique en ligne et Planity intégré | AE35: Non | AF35: Non | AG35: Non | AH35: 0
A36: Bulles de Beauté Caluire | B36: Institut de beauté / Spa | C36: Caluire-et-Cuire | D36: +33 4 78 72 32 48 | F36: Vrai site | G36: https://bullesdebeaute.fr/ | H36: Oui | I36: https://www.instagram.com/bullesdebeaute.institut/ | J36: Oui | K36: https://www.facebook.com/institut.bullesdebeaute/ | L36: Cécile | M36: Gérante | N36: Oui | O36: Professionnel | P36: 4.8 | Q36: 23 | R36: Site récent et optimisé | AE36: Non | AF36: Non | AG36: Non | AH36: 0
A37: Espace Coiffure par Cecile Andine | B37: Salon de coiffure | C37: Caluire-et-Cuire | D37: 04 78 08 29 03 | E37: andinececile@outlook.fr | F37: Planity | G37: https://www.planity.com/espace-coiffure-par-cecile-andine-69300-caluire-et-cuire | H37: Oui | I37: https://www.instagram.com/espacecoiffureca/ | J37: Oui | K37: https://www.facebook.com/profile.php?id=100063564190783# | L37: Cécile | M37: Gérante | N37: Oui | O37: Inexistant | P37: 4.8 | Q37: 40 | R37: Pas de site _ Fiche Google ok | S37: 46192 | T37: 0.73263889 | U37: Oui | V37: 15 | W37: À rappeler | X37: Planning rempli | Y37: Pas intéressé | Z37: SMS envoyé pour proposition du site à 300€ | AA37: 46222 | AB37: Appel | AC37: À faire
A38: Catalina Esthéticienne Caluire | B38: Institut beauté / Minceur | C38: Caluire-et-Cuire | D38: +33 6 13 12 57 11 | E38: catacalad@gmail.com | F38: Vrai site | G38: https://www.catalinabeauty.fr/ | H38: Oui | I38: https://www.instagram.com/catalinaestradacalad/ | J38: Oui | K38: https://www.facebook.com/mybeautyspa.world/ | L38: Catalina | M38: Gérante | N38: Non | O38: Professionnel | P38: 5.0 | Q38: 39 | R38: Bon site avec lien vers Planity - Juste pas bon lien Facebook sur fiche Google | AE38: Non | AF38: Non | AG38: Non | AH38: 0
A39: Well&Com' Massages bien-être | B39: Massage bien-être | C39: Caluire-et-Cuire | D39: +33 6 61 96 01 06 | E39: wellandcom69110@gmail.com | F39: Vrai site | G39: https://www.wellandcomassages.fr/ | H39: Oui | I39: https://www.instagram.com/wellandcom/ | J39: Oui | K39: https://www.facebook.com/wellandcommassages2 | L39: Sandrine | M39: Praticienne | N39: Oui | O39: Professionnel | P39: 5.0 | Q39: 42 | R39: Rien à redire - Lien Planity sur site pour prise de RDV | AE39: Non | AF39: Non | AG39: Non | AH39: 0
A40: Laurence C Coiffure | B40: Salon de coiffure | C40: Miribel | D40: +33 4 72 88 27 03 | F40: Autre | G40: https://www.kalendes.com/site/laurenceccoiffure/welcome | H40: Oui | I40: https://www.instagram.com/laurence_c._coiffure/ | J40: Oui | K40: https://www.facebook.com/malo711 | L40: Laurence | M40: Gérante | N40: Oui | O40: Mauvais | P40: 5.0 | Q40: 71 | R40: Pas de site internet plateforme Kalendes | S40: 46192 | AE40: Non | AF40: Non | AG40: Non | AH40: 0
...

Sheet 📊 Tableau de bord
A1: N' Studio Digital — Tableau de bord prospection
A2: Votre site web, votre meilleur commercial.
A4: STATUT | B4: NOMBRE | C4: % TOTAL
A5: Non joint | B5: =COUNTIF('Suivi Prospects'!W:W,A5) -> 5 | C5: =IFERROR(B5/SUM(B5:B9),0) -> 0.13513514
A6: Refus | B6: =COUNTIF('Suivi Prospects'!W:W,A6) -> 19 | C6: =IFERROR(B6/SUM(B5:B9),0) -> 0.51351351
A7: À rappeler | B7: =COUNTIF('Suivi Prospects'!W:W,A7) -> 12 | C7: =IFERROR(B7/SUM(B5:B9),0) -> 0.32432432
A8: Intéressé | B8: =COUNTIF('Suivi Prospects'!W:W,A8) -> 1 | C8: =IFERROR(B8/SUM(B5:B9),0) -> 0.027027027
A9: RDV pris | B9: =COUNTIF('Suivi Prospects'!W:W,A9) -> 0 | C9: =IFERROR(B9/SUM(B5:B9),0) -> 0
A10: TOTAL | B10: =SUM(B5:B9) -> 37 | C10: =IFERROR(SUM(B5:B9)/SUM(B5:B9),0) -> 1
E12: TOTAL PROSPECTS | F12: RDV PRIS | G12: CLIENTS SIGNÉS | H12: CA TOTAL (€) | I12: TAUX DE CONTACT
E13: =COUNTA('Suivi Prospects'!A5:A491) -> 181 | F13: =COUNTIF('Suivi Prospects'!W5:W491,"RDV pris") -> 0 | G13: =COUNTIF('Suivi Prospects'!AG5:AG491,"Oui") -> 0 | H13: =SUMIF('Suivi Prospects'!AG5:AG491,"Oui",'Suivi Prospects'!AH5:AH491) -> 0 | I13: =IFERROR(COUNTIF('Suivi Prospects'!U5:U491,"Oui")/COUNTA('Suivi Prospects'!A5:A491),0) -> 0.1160221
E15: 🔥 ASTUCE PRO — Rappeler en priorité les prospects avec Score 4 et 5
E16: 🎯 Objectif : 20 à 30 appels/jour — Relancer chaque matin — Remplir en live

Sheet 📋 Guide utilisation
A1: N' Studio Digital — Guide d'utilisation du fichier prospects
A3: 🔹 COMMENT UTILISER CE FICHIER
A5: Onglet principal | B5: → 'Suivi Prospects' : saisir chaque prospect en live pendant l'appel
A6: Tableau de bord | B6: → '📊 Tableau de bord' : visualiser vos stats en temps réel, se met à jour automatiquement
A8: 🔹 LES COLONNES CLÉS
A10: Score 🔥 (1 à 5) | B10: PRIORITÉ ABSOLUE — Rappeler d'abord les 4 et 5. Ne pas perdre de temps sur les 1 et 2.
A11: Statut appel | B11: Choisir dans la liste déroulante : Non joint / Refus / À rappeler / Intéressé / RDV pris
A12: Commentaire libre 📝 | B12: COLONNE LA PLUS IMPORTANTE — Ton ressenti, infos perso, contexte business. Sois précise !
A13: Date relance | B13: À remplir SYSTÉMATIQUEMENT si le statut est 'À rappeler' ou 'Intéressé'
A14: Besoin identifié | B14: Ce que le prospect t'a dit — choisir dans la liste
A15: Objection | B15: Ce qu'il t'a opposé — utile pour préparer la relance
A17: 🔹 WORKFLOW QUOTIDIEN
A19: Matin (9h-10h) | B19: → Vérifier les 'Date relance' du jour → Rappeler en priorité les scores 4 et 5
A20: Journée | B20: → 20 à 30 appels → Remplir chaque ligne EN LIVE pendant l'appel
A21: Fin de journée | B21: → Mettre à jour les statuts → Planifier les relances du lendemain
A23: 🔹 CODES COULEURS STATUTS
A25: Jaune clair | B25: Non joint — à rappeler prochainement
A26: Rouge clair | B26: Refus — ne plus contacter
A27: Bleu clair | B27: À rappeler — date de relance fixée
A28: Vert clair | B28: Intéressé — à traiter en priorité
A29: Violet clair | B29: RDV pris — préparer l'entretien
A31: 🔹 RAPPEL BASELINE
A33: N' Studio Digital | B33: Votre site web, votre meilleur commercial.
A34: Contact | B34: contact@nstudiodigital.fr

Sheet 📝 Suivi clients
A1: N' Studio Digital — Suivi des formulaires clients
A2: IDENTIFICATION | D2: CONTACT | F2: PROJET | H2: TYPE DE SITE | I2: PRÉSENCE EN LIGNE | K2: VISUELS & IDENTITÉ | M2: FONCTIONNALITÉS | N2: CIBLE | O2: STATUT | P2: PRIORITÉ | Q2: DATE RÉCEPTION | R2: DATE RELANCE | S2: NOTES
A3: N° Client | B3: Nom entreprise | C3: Nom / Prénom | D3: Email | E3: Réseaux / Site actuel | F3: Activité | G3: Objectifs du site | H3: Type de site souhaité | I3: Présence en ligne | J3: Liens sociaux | K3: Éléments visuels disponibles | L3: Sites de référence | M3: Fonctionnalités souhaitées | N3: Clientèle cible | O3: Statut | P3: Priorité | Q3: Date réception | R3: Date relance | S3: Notes / Remarques
A4: =IF(B4<>"",ROW()-3,"")
A5: =IF(B5<>"",ROW()-3,"")
A6: =IF(B6<>"",ROW()-3,"")
A7: =IF(B7<>"",ROW()-3,"")
A8: =IF(B8<>"",ROW()-3,"")
A9: =IF(B9<>"",ROW()-3,"")
A10: =IF(B10<>"",ROW()-3,"")
A11: =IF(B11<>"",ROW()-3,"")
A12: =IF(B12<>"",ROW()-3,"")
A13: =IF(B13<>"",ROW()-3,"")
A14: =IF(B14<>"",ROW()-3,"")
A15: =IF(B15<>"",ROW()-3,"")
... A23: =IF(B23<>"",ROW()-3,"")

Sheet 📝 Tableau de bord
A1: N' Studio Digital — Tableau de bord
A3: Total clients | B3: À contacter | C3: Brief reçu | D3: En cours | E3: Livrés | F3: Urgents
A4: =COUNTA('📝 Suivi clients'!B4:B23) -> 0 | B4: =COUNTIF('📝 Suivi clients'!O4:O23,"À contacter") -> 0 | C4: =COUNTIF('📝 Suivi clients'!O4:O23,"Brief reçu") -> 0 | D4: =COUNTIF('📝 Suivi clients'!O4:O23,"En cours") -> 0 | E4: =COUNTIF('📝 Suivi clients'!O4:O23,"Livré") -> 0 | F4: =COUNTIF('📝 Suivi clients'!P4:P23,"🔴 Urgent") -> 0
A6: Répartition par statut
A7: À contacter | B7: =COUNTIF('📝 Suivi clients'!O4:O23,"À contacter") -> 0 | C7: =IF(B7=0,"—",TEXT(B7/B4,"0%")) -> —
A8: En attente | B8: =COUNTIF('📝 Suivi clients'!O4:O23,"En attente") -> 0 | C8: =IF(B8=0,"—",TEXT(B8/B4,"0%")) -> —
A9: Brief reçu | B9: =COUNTIF('📝 Suivi clients'!O4:O23,"Brief reçu") -> 0 | C9: =IF(B9=0,"—",TEXT(B9/B4,"0%")) -> —
A10: En cours | B10: =COUNTIF('📝 Suivi clients'!O4:O23,"En cours") -> 0 | C10: =IF(B10=0,"—",TEXT(B10/B4,"0%")) -> —
A11: Livré | B11: =COUNTIF('📝 Suivi clients'!O4:O23,"Livré") -> 0 | C11: =IF(B11=0,"—",TEXT(B11/B4,"0%")) -> —
A12: Archivé | B12: =COUNTIF('📝 Suivi clients'!O4:O23,"Archivé") -> 0 | C12: =IF(B12=0,"—",TEXT(B12/B4,"0%")) -> —

Sheet 📝 Questions formulaire
A1: Référence — Questions du formulaire N' Studio Digital
A3: 1 | B3: Nom de votre entreprise / organisation | C3: Obligatoire
A4: 2 | B4: Votre nom et prénom | C4: Obligatoire
A5: 3 | B5: Adresse e-mail de contact | C5: Obligatoire
A6: 4 | B6: Décrivez brièvement votre activité | C6: Obligatoire
A7: 5 | B7: Quels sont vos objectifs principaux pour ce site internet ? | C7: Obligatoire
A8: 6 | B8: Quel type de site souhaitez-vous ? | C8: Obligatoire — Choix multiple
A9: 7 | B9: Avez-vous déjà une présence en ligne ? | C9: Obligatoire — Choix multiple
A10: 8 | B10: Liens de vos réseaux sociaux ou site internet | C10: Facultatif
A11: 9 | B11: Image / ambiance souhaitée pour votre site | C11: Facultatif ⚠️ (suggéré : rendre obligatoire)
A12: 10 | B12: Sites de référence ou exemples qui vous plaisent | C12: Obligatoire
A13: 11 | B13: Éléments visuels disponibles pour votre marque | C13: Obligatoire — Choix multiple
A14: 12 | B14: Fonctionnalités souhaitées | C14: Obligatoire — Choix multiple
... A16: 14 | B16: Autres informations ou précisions utiles | C16: Facultatif

Sheet Listes
A1: Liste_SiteWeb | B1: Liste_OuiNon | C1: Liste_QualiteSite | D1: Liste_StatutAppel | E1: Liste_Besoin | F1: Liste_Objection | G1: Liste_CanalRelance | H1: Liste_StatutRelance | I1: Liste_Score
A2: Planity | B2: Oui | C2: Professionnel | D2: Non joint | E2: Manque de clients | F2: Pas intéressé | G2: Appel | H2: À faire | I2: 5 🔥🔥🔥
A3: Treatwell | B3: Non | C3: Passable | D3: Refus | E3: Veut développer | F3: Pas le temps | G3: Mail | H3: Fait | I3: 4 🔥🔥
A4: Wix / Squarespace / Jimdo | C4: Mauvais | D4: À rappeler | E4: Dépend du bouche-à-oreille | F4: Déjà un site | G4: SMS | H4: Annulé | I4: 3 🌡
A5: Vrai site | C5: Inexistant | D5: Intéressé | E5: Planning rempli | F5: Trop cher | I5: 2 ❄
A6: Lien réseaux sociaux | D6: RDV pris | E6: Aucun besoin | F6: Autre | I6: 1 ❄❄
A7: Aucun
A8: Autre
